{"name": "test_with_bug", "status": "skipped", "statusDetails": {"message": "XFAIL Найден баг в приложении, из-за которого тест падает с ошибкой\n\nAssertionError: assert 1 == 2", "trace": "@pytest.mark.xfail(reason='Найден баг в приложении, из-за которого тест падает с ошибкой')\n    def test_with_bug():\n>       assert 1 == 2\nE       assert 1 == 2\n\ntests/pytest/test_pytest_xfail.py:6: AssertionError"}, "start": 1751219706387, "stop": 1751219706387, "uuid": "433b78ff-454b-487d-8351-fad8fe10ee10", "historyId": "fb30392daae1117f9ea61a430455c804", "testCaseId": "fb30392daae1117f9ea61a430455c804", "fullName": "tests.pytest.test_pytest_xfail#test_with_bug", "labels": [{"name": "parentSuite", "value": "tests.pytest"}, {"name": "suite", "value": "test_pytest_xfail"}, {"name": "host", "value": "MacBook-Pro-Tochka-2.local"}, {"name": "thread", "value": "88573-MainThread"}, {"name": "framework", "value": "pytest"}, {"name": "language", "value": "cpython3"}, {"name": "package", "value": "tests.pytest.test_pytest_xfail"}]}