{"name": "test_external_services_is_unavailable", "status": "skipped", "statusDetails": {"message": "XFAIL Внешний сервис временно недоступен\n\nAssertionError: assert 1 == 2", "trace": "@pytest.mark.xfail(reason='Внешний сервис временно недоступен')\n    def test_external_services_is_unavailable():\n>       assert 1 == 2\nE       assert 1 == 2\n\ntests/pytest/test_pytest_xfail.py:16: AssertionError"}, "start": 1751219706393, "stop": 1751219706393, "uuid": "d2f6778f-e276-48fa-a28b-dacca1b97a50", "historyId": "c31bdd1d9b512b2657ee78e974ae667c", "testCaseId": "c31bdd1d9b512b2657ee78e974ae667c", "fullName": "tests.pytest.test_pytest_xfail#test_external_services_is_unavailable", "labels": [{"name": "parentSuite", "value": "tests.pytest"}, {"name": "suite", "value": "test_pytest_xfail"}, {"name": "host", "value": "MacBook-Pro-Tochka-2.local"}, {"name": "thread", "value": "88573-MainThread"}, {"name": "framework", "value": "pytest"}, {"name": "language", "value": "cpython3"}, {"name": "package", "value": "tests.pytest.test_pytest_xfail"}]}